<?xml version="1.0" encoding="utf-8"?>
<!-- This URDF was automatically created by SolidWorks to URDF Exporter! Originally created by Stephen Brawner (brawner@gmail.com) 
     Commit Version: 1.5.1-0-g916b5db  Build Version: 1.5.7152.31018
     For more information, please see http://wiki.ros.org/sw_urdf_exporter -->
<robot
  name="Libra_PyBullet_01.SLDASM">
  <link
    name="Sphere">
    <inertial>
      <origin
        xyz="0 0 0.23"
        rpy="0 0 0" />
      <mass
        value="3.0" />
      <inertia
        ixx="0.1"
        ixy="0.0"
        ixz="0.0"
        iyy="0.1"
        iyz="0.0"
        izz="0.1" />
    </inertial>
    <visual>
      <origin
        xyz="0 0 0"
        rpy="0 0 0" />
      <geometry>
        <mesh
          filename="Sphere.STL" />
      </geometry>
      <material
        name="">
        <color
          rgba="1.0 0.0 0.0 0.4" />
      </material>
    </visual>
    <collision>
      <origin
        xyz="0 0 0"
        rpy="0 0 0" />
      <geometry>
        <mesh
          filename="Sphere.STL" />
      </geometry>
    </collision>
  </link>

  
  <link
    name="Pendulum">
    <inertial>
      <origin
        xyz="0 0 -0.38"
        rpy="0 0 0" />
      <mass
        value="1" />
      <inertia
        ixx="0.01"
        ixy="0"
        ixz="0"
        iyy="0.01"
        iyz="0"
        izz="0.01" />
    </inertial>
    <visual>
      <origin
        xyz="0 0 -0.23"
        rpy="0 0 0" />
      <geometry>
        <mesh
          filename="Pendulum.STL" />
      </geometry>
      <material
        name="">
        <color
          rgba="0.79216 0.81961 0.93333 1" />
      </material>
    </visual>
    <collision>
      <origin
        xyz="0 0 -0.23"
        rpy="0 0 0" />
      <geometry>
        <mesh
          filename="Pendulum.STL" />
      </geometry>
    </collision>
  </link>

  
  <joint
    name="Revolute_1"
    type="continuous">
    <origin
      xyz="0 0 0.23"
      rpy="0 0 3.1416" />
    <parent
      link="Sphere" />
    <child
      link="Pendulum" />
    <axis
      xyz="0 1 0"
 />
    <limit
      lower="0"
      upper="0"
      effort="0"
      velocity="0" />
  </joint>
  
  <link
    name="Slider">
    <inertial>
      <origin
        xyz="0 0 0.15"
        rpy="0 0 0" />
      <mass
        value="0.5" />
      <inertia
        ixx="0.01"
        ixy="0"
        ixz="0"
        iyy="0.01"
        iyz="0"
        izz="0.01" />
    </inertial>
    <visual>
      <origin
        xyz="0 0 -0.23"
        rpy="0 0 0" />
      <geometry>
        <mesh
          filename="Slider.STL" />
      </geometry>
      <material
        name="">
        <color
          rgba="0.79216 0.81961 0.93333 1" />
      </material>
    </visual>
    <collision>
      <origin
        xyz="0 0 -0.23"
        rpy="0 0 0" />
      <geometry>
        <mesh
          filename="Slider.STL" />
      </geometry>
    </collision>
  </link>
  

  <joint
    name="Sliding"
    type="prismatic">
    <origin
      xyz="0 0 0"
      rpy="0 0 3.1416" />
    <parent
      link="Pendulum" />
    <child
      link="Slider" />
    <axis
      xyz="0 1 0" />
    <limit
      lower="-0.2"
      upper="0.2"
      effort="0"
      velocity="0" />
  </joint>
</robot>
